Workbook

Sheet Main
A1: DOCMEE
A2: Command Center — planning & build tracker
A3: AI chatbot platform for clinics · single source of truth · all data live
A5: KEY METRICS
A6: Phases sealed | C6: =COUNTIF(Progress!E5:E16,"Sealed")&" / 12" -> 12 / 12
A7: Decisions locked | C7: =COUNTA('Decisions Index'!A2:A80)-COUNTIF('Decisions Index'!D2:D80,"FLAGGED*")-COUNTIF('Decisions Index'!D2:D80,"PENDING*") -> 64
A8: Decisions parked (revisit) | C8: =COUNTIF('Decisions Index'!D2:D80,"FLAGGED*")+COUNTIF('Decisions Index'!D2:D80,"PENDING*") -> 0
A9: Open risks (Med-High +) | C9: =COUNTIF('Risk Register'!G2:G14,"Med-High")+COUNTIF('Risk Register'!G2:G14,"High") -> 1
A10: Security items open | C10: =COUNTIF('Security Audit'!H2:H26,"Open*") -> 5
A11: Requirements partial/gap | C11: =COUNTIF('Platform Requirements'!D5:D36,"Partial")+COUNTIF('Platform Requirements'!D5:D36,"Gap") -> 1
A12: Est. dev hours (plan) | C12: ='Cost Tracker'!D25 -> 650
A13: Actual hours logged | C13: ='Cost Tracker'!E25 -> 5
A14: AI uses logged | C14: ='Cost Tracker'!G25 -> 24
A15: Grand cost (to date) | C15: ='Cost Tracker'!I25 -> 112
A17: TABS · all hidden — right-click the Main tab ► Unhide to open any sheet
A18: ▸ Overview | E18: ▸ Risk Register
A19: ▸ Action Tracker | E19: ▸ Phase Gates
A20: ▸ Decisions Index | E20: ▸ Progress (Gantts)
A21: ▸ Platform Requirements | E21: ▸ Security Audit
A22: ▸ Cost Tracker | E22: ▸ Gaps
A23: ▸ Pros | E23: ▸ Cons
A24: ▸ Future Improvements | E24: ▸ Update Log
A25: ▸ Build Backlog | E25: ▸ Dev Plan
A26: To open a sheet: right-click the 'Main' tab at the bottom ► Unhide ► choose the sheet. (Excel desktop / Google Sheets: View ► Hidden sheets.)
A28: OPEN DECISIONS & GAPS
A29: • PLANNING COMPLETE — 12 phases sealed + cross-cutting retention/observability/compliance (GDPR-baseline) locked. Next: build.
A30: • Pre-launch actions: testing/QA execution (X19) · Guatemalan data-protection counsel review (X20) · backups (X12) · deflection sign-off (X14)
A31: • Deferred by design (FI1–FI8): live calendar sync · self-host LLM · license · native app · billing · smarter merge · bot reschedule/cancel · broadcast
A32: • Build-time gates (Phase Gates tab) + per-clinic onboarding (X1–X18) handled during implementation
A34: CONFIDENCE (Phase 0 → 3D) · flag line = below 8.0
A35: Total decisions scored | C35: =COUNT('Decisions Index'!E2:E80) -> 64
A36: Average confidence | C36: =ROUND(AVERAGE('Decisions Index'!E2:E80),2) -> 8.48
A37: Lowest score | C37: =MIN('Decisions Index'!E2:E80) -> 7.5
A38: Decisions ≥ 9.0 | C38: =COUNTIF('Decisions Index'!E2:E80,">=9") -> 6
A39: Decisions = 8.5 | C39: =COUNTIF('Decisions Index'!E2:E80,8.5) -> 50
A40: Decisions = 8.0 (lowest locked tier) | C40: =COUNTIF('Decisions Index'!E2:E80,8) -> 7
A41: Decisions below 8.0 (FLAGGED) | C41: =COUNTIF('Decisions Index'!E2:E80,"<8") -> 1
A43: 🚩 Below 8.0: 2B / cross-channel identity merge = 7.5 — deliberate manual-merge (avoids PHI-mixing); recorded as a Con + FI6. Knowingly flagged, not an oversight.
A44: At 8.0 (watch list): 1B Data capture · 2A Notifications · 2B Unified inbox · 3A Doctor routing · 3B Flow builder · 3B Secretary copilot · 3C Sheets/CRM export

Sheet Overview
A1: Docmee — Project Trackers
A2: Consolidated living workbook · risks, external actions, phase gates, decisions, update log
A3: Last updated: 13 June 2026
A5: Phase status (all 12 phases)
A6: Phase | B6: Status
A7: 0 — Foundation | B7: Sealed
A8: 1A — Core Inbox + Bot | B8: Sealed
A9: 1B — Human Inbox + Patient Data | B9: Sealed
A10: 1C — Scheduling | B10: Sealed
A11: 2A — Multi-User Operations | B11: Sealed
A12: 2B — Channels | B12: Sealed
A13: 2C — Automation & Templates | B13: Sealed
A14: 2D — Analytics & Search | B14: Sealed
A15: 3A — Multi-Doctor | B15: Sealed
A16: 3B — Advanced Intake | B16: Sealed
A17: 3C — Integrations & OCR | B17: Sealed
A18: 3D — Mobile / PWA / Push | B18: Sealed
A20: Summary (live counts — recomputed each run)
A21: Metric | B21: Count
A22: Risks — Med-High priority | B22: =COUNTIF('Risk Register'!G2:G14,"Med-High") -> 1
A23: Risks — Medium priority | B23: =COUNTIF('Risk Register'!G2:G14,"Medium") -> 4
A24: Risks — Low priority | B24: =COUNTIF('Risk Register'!G2:G14,"Low") -> 8
A25: Actions — Not started | B25: =COUNTIF('Action Tracker'!F2:F21,"Not started") -> 15
A26: Actions — In progress | B26: =COUNTIF('Action Tracker'!F2:F21,"In progress") -> 2
A27: Actions — Blocked/waiting | B27: =COUNTIF('Action Tracker'!F2:F21,"Blocked/waiting") -> 1
A28: Actions — Closed | B28: =COUNTIF('Action Tracker'!F2:F21,"Closed*") -> 1
A29: Actions — Parked | B29: =COUNTIF('Action Tracker'!F2:F21,"Parked") -> 1
A30: Phases — Sealed | B30: =COUNTIF(B7:B18,"Sealed") -> 12
A31: Security — Open items | B31: =COUNTIF('Security Audit'!H2:H26,"Open*") -> 5
A32: Requirements — Partial/Gap (to address) | B32: =COUNTIF('Platform Requirements'!D5:D36,"Partial")+COUNTIF('Platform Requirements'!D5:D36,"Gap") -> 1
A33: Legend
A34: Term | B34: Meaning
A35: Owner | B35: Clinic = end-user clinic · Docmee = Docmee team
A36: Path | B36: Dev path = blocks the build · Off dev path = does not block the build
A37: Priority | B37: High / Med-High / Medium / Low (likelihood × severity)
A38: Tabs | B38: Risks · Actions · Gates · Decisions · Gaps · Pros · Cons · Progress · Security Audit · Future Improvements

Sheet Risk Register
A1: ID | B1: Risk | C1: Owner | D1: Affects | E1: Likelihood | F1: Severity | G1: Priority | H1: Path | I1: Disposition / Status
A2: R1 | B2: Meta asset transfer / WhatsApp setup (already verified, same entity) | C2: Clinic | D2: Per-clinic go-live | E2: Low | F2: Med | G2: Low | H2: Off dev path | I2: Largely retired — routine; clinic-owned
A3: R2 | B3: Message-template approval (2C, outside 24h window) | C3: Clinic | D3: Per-clinic 2C automation | E3: Med | F3: Med | G3: Low | H3: Off dev path | I3: Clinic responsibility; Docmee may supply content
A4: R3 | B4: Legal docs (privacy policy, terms, Spanish) | C4: Clinic | D4: Per-clinic launch | E4: Med | F4: Med | G4: Medium | H4: Off dev path | I4: Open — clinic-owned; Docmee supplies template (X11)
A5: R4 | B5: App-layer encryption breaks SQL filtering | C5: Docmee | D5: Patient lookup, matching, dedupe | E5: Low | F5: Med | G5: Low | H5: Dev path | I5: De-risked & locked: separate stable HMAC key; DAL lookups; ciphertext never in WHERE
A6: R5 | B6: RLS cross-tenant carve-out done wrong → isolation leak | C6: Docmee | D6: Workers, metrics, DLQ, IA Studio | E6: Low | F6: High | G6: Low | H6: Dev path | I6: De-risked & locked: named admin role + withAdminContext() + allowlist + audit
A7: R6 | B7: Single-clinic-per-user may not fit a clinic-group customer | C7: Docmee | D7: Auth/JWT/RLS if revisited | E7: Low | F7: Med-High | G7: Low | H7: Dev path | I7: Accepted — one-to-one locked; bounded future migration
A8: R7 | B8: Unofficial WhatsApp gateway (Evolution) for interim/live traffic | C8: Docmee tech/ops | D8: Channel continuity; PHI custody | E8: Med | F8: High | G8: Medium | H8: Off dev path | I8: Accepted — bounded by interim use + supervision; prompt X10 cutover
A9: R8 | B9: Single-VPS = single point of failure | C9: Docmee tech/ops | D9: Availability once real clinics depend | E9: Med | F9: High (Low w/ backups) | G9: Medium | H9: Off dev path | I9: Redundancy deferred (X13); backups REQUIRED before real patients (X12)
A10: R9 | B10: Document ingestion expands Phase 1A scope | C10: Docmee | D10: 1A timeline; embedding spend | E10: Med-High | F10: Med | G10: Med-High | H10: Dev path | I10: Open — mitigated (text-layer, off-the-shelf libs, OCR→3C); fallback end-1A/early-1B
A11: R10 | B11: Bot mis-handles a distress message (booking-only clinics) | C11: Docmee + Clinic | D11: Reputation; liability | E11: Low | F11: Med | G11: Medium | H11: Safety | I11: Reduced — minimal deflection guardrail; clinic sign-off (X14)
A12: R11 | B12: Cross-channel / duplicate patient records | C12: Docmee | D12: CRM data quality; history continuity | E12: Med | F12: Low-Med | G12: Low | H12: Dev path | I12: Mitigated — manual staff-merge in 2B (audited, confirmation); smarter auto/suggested/reversible merge → FI6
... A14: R13 | B14: Bot patient-data mis-capture (extraction accuracy) | C14: Docmee | D14: CRM data quality | E14: Med | F14: Low | G14: Low | H14: Dev path | I14: Accepted/mitigated — confidence-gating (verified vs suggested), secretary-edits-win, per-field source, no deletes, full audit; tune on real traffic

Sheet Action Tracker
A1: ID | B1: Item | C1: Owner | D1: Blocks / Needed by | E1: Lead time | F1: Status
A2: X1 | B2: Transfer Meta (WhatsApp/WABA) asset into Docmee/clinic app | C2: Clinic | D2: Per-clinic go-live (off dev path) | E2: ~Days | F2: In progress
A3: X2 | B3: Interim WhatsApp connectivity via self-hosted Evolution API (supervised, interim) | C3: Docmee tech | D3: Phase 0 Track A + early onboarding | E3: Days | F3: In progress
A4: X3 | B4: Draft + publish privacy policy & terms (Spanish) | C4: Clinic | D4: Per-clinic launch (off dev path) | E4: 1–2 weeks | F4: Not started
A5: X4 | B5: Draft + submit WhatsApp message templates | C5: Clinic (Docmee content) | D5: Per-clinic 2C (off dev path) | E5: 1–3 wks/batch | F5: Not started
A6: X5 | B6: Provision third-party API creds — Docmee platform keys (Model A); transcription provider-abstracted | C6: Docmee | D6: 1A end-to-end (not start) | E6: Hours–days | F6: Not started
A7: X6 | B7: Stand up Supabase + Redis + VPS + DNS (+ Storage) | C7: Docmee | D7: Phase 0 deploy target | E7: Hours–days | F7: Not started
A8: X7 | B8: Per-clinic WhatsApp display-name approval + number (Cloud API) | C8: Clinic | D8: Per-clinic go-live official API (off dev path) | E8: Days | F8: Blocked/waiting
A9: X8 | B9: Encryption key source | C9: Docmee | D9: Phase 0 | E9: — | F9: Closed — Supabase Vault + envelope + key_version; host-store fallback
A10: X9 | B10: Stand up & maintain self-hosted Evolution API in Docmee infra | C10: Docmee tech | D10: X2 interim + 1A end-to-end testing | E10: Days | F10: Not started
A11: X10 | B11: Per-clinic cutover: Evolution → Meta Cloud API | C11: Docmee tech | D11: End-state channel per clinic | E11: Per clinic | F11: Not started
A12: X11 | B12: Clinic onboarding-support checklist/guide | C12: Docmee | D12: Smooth onboarding; protects launch | E12: Days | F12: Not started
... A21: X20 | B21: Guatemalan data-protection counsel review — consent, retention, health-data + export obligations; confirm GDPR-baseline design (complements X3 privacy policy) | C21: Docmee + local counsel | D21: Before real patient traffic | E21: Days | F21: Not started

Sheet Phase Gates
A1: Phase | B1: # | C1: Gate criterion (pass/fail) | D1: Result | E1: Notes
A2: 0 | B2: 1 | C2: Inbound message stored, normalized, scoped to correct clinic_id | D2: Pending
A3: 0 | B3: 2 | C3: Cross-tenant read denied at the DB (RLS proven) | D3: Pending
A4: 0 | B4: 3 | C4: Worker assumes clinic context (SET LOCAL); admin role only cross-tenant path | D4: Pending
A5: 0 | B5: 4 | C5: Redelivered wamid → exactly one row (idempotency) | D5: Pending
A6: 0 | B6: 5 | C6: Outbound delivers; send to opted-out patient blocked at chokepoint | D6: Pending
A7: 0 | B7: 6 | C7: Unknown phone_number_id logged + metric + dropped (no crash/row) | D7: Pending
A8: 0 | B8: 7 | C8: Ciphertext at rest; HMAC lookup resolves; key_version recorded | D8: Pending
A9: 0 | B9: 8 | C9: Clinic JWT scoped; platform users only via logged impersonation | D9: Pending
A10: 0 | B10: 9 | C10: Migrations apply clean forward from empty DB; /health/ready green | D10: Pending
A11: 1A | B11: 1 | C11: KB entries + text-layer doc → chunks embedded → review→live; retrieval ≥0.70; rules injected | D11: Pending
A12: 1A | B12: 2 | C12: Intent + routing; taken-over conv never auto-replies; distress → deflection; no reply without decision token | D12: Pending
A13: 1A | B13: 3 | C13: KB-covered question → grounded answer; no-KB → acknowledge + handoff (no hallucination) | D13: Pending
... A20: 1A | B20: 10 | C20: Failed embedding job → retry → mark chunk failed + flag doc incomplete; others unaffected | D20: Pending
A21: 1B | B21: 1 | C21: Patient auto-created on first contact; clinic-scoped one-per-identity | D21: Pending | E21: Q1 (in progress)
A22: 1B | B22: 2 | C22: Patient progressively enriched; valid with identity only | D22: Pending | E22: Q1
A23: 1B | B23: 3 | C23: patient_id backfilled onto 1A conversations; inbound resolves-or-creates | D23: Pending | E23: Q1
A24: 1B | B24: 4 | C24: Functional patient profile: history, tags, statuses, notes, search/filter | D24: Pending | E24: Q2
A25: 1B | B25: 5 | C25: Shared queue + claim; reply/takeover auto-assigns; reassign allowed | D25: Pending | E25: Q2
A26: 1B | B26: 6 | C26: Free-form multi-tags + patient status; conversation state = mode (no duplicate) | D26: Pending | E26: Q2
A27: 1B | B27: 7 | C27: Patient-level internal notes (authored + timestamped, staff-only) | D27: Pending | E27: Q2
A28: 1B | B28: 8 | C28: Inbox filters (mode/assignment/tags/status/date) + patient-identity search | D28: Pending | E28: Q2
A29: 1B | B29: 9 | C29: Bot captures name/reason via tool-calling → validated DAL writes (field-level, logged, no deletes) | D29: Pending | E29: Q3
A30: 1B | B30: 10 | C30: Ambiguous capture confirmed or written as suggested (not committed); never fabricates | D30: Pending | E30: Q3
A31: 1B | B31: 11 | C31: Per-field source (bot/staff); secretary-set fields locked from bot overwrite | D31: Pending | E31: Q3
A32: 1B | B32: 12 | C32: Handoff/distress → urgent notification (panel + email); new lead → panel; visible until acknowledged | D32: Pending | E32: Q4
... A89: 3D | B89: 3 | C89: PWA reaches parity on secretary daily-driver ops (inbox, bot control, appointments, alerts, notes) | D89: Pending | E89: Q3

Sheet Decisions Index
A1: Phase | B1: Area | C1: Locked decision (summary) | D1: Confidence | E1: Score /10 | F1: Flagged | G1: Reason if < 8 | H1: Record
A2: 0 | B2: Worker RLS | C2: SET LOCAL app.clinic_id per job; audited admin role for cross-tenant | D2: High | E2: 8.5 | H2: phase-0
A3: 0 | B3: Encryption | C3: App-layer envelope; key in Supabase Vault; key_version; separate stable HMAC key | D3: High | E3: 8.5 | H3: phase-0
A4: 0 | B4: Identities | C4: platform_users vs clinic_users disjoint; impersonation only | D4: High | E4: 9 | H4: phase-0
A5: 0 | B5: Tenancy | C5: User↔clinic one-to-one; doctor seam dormant → 3A | D5: High | E5: 8.5 | H5: phase-0
A6: 0 | B6: Opt-out | C6: opted_out flag, all-stop, outbound chokepoint, bot-irreversible | D6: Mkt-std | E6: 9 | H6: phase-0
A7: 0 | B7: Loop | C7: Pipes only; no auto patient replies (first reply = 1A) | D7: High | E7: 9 | H7: phase-0
A8: 0 | B8: Idempotency | C8: provider_message_id unique; insert-on-conflict-ignore | D8: High | E8: 9 | H8: phase-0
A9: 0 | B9: Deploy | C9: Single-VPS all-in-one for pilot; Supabase managed | D9: High | E9: 8.5 | H9: phase-0
A10: 0 | B10: Mechanisms | C10: SQL migrations+runner; withClinicContext; bootstrap; liveness/readiness; Vault boot; webhook handshake | D10: High | E10: 8.5 | H10: phase-0
A11: 1A | B11: KB | C11: Unified substrate (manual + doc chunks); rules always-injected; 0.70; text-layer ingestion | D11: High | E11: 8.5 | H11: phase-1a
A12: 1A | B12: Pipeline | C12: 5 intents; ordered gate chain (takeover→safety→confidence→intent); decision-token outbound | D12: High | E12: 9 | H12: phase-1a
A13: 1A | B13: Prompt | C13: role→rules→KB→contract; ~10 turns; fail-safe truncation; cacheable prefix | D13: High | E13: 8.5 | H13: phase-1a
... A37: 2B | B37: Unified inbox | C37: All channels in one inbox (channel badge per conversation); CRM/inbox channel-agnostic (1B); per-channel messaging-window rules enforced at outbound; bot replies identically across channels | D37: High | E37: 8 | H37: phase-2b
A38: 2B | B38: Identity merge | C38: Manual merge only — secretary explicitly merges two patient records (audited, confirmation step); no auto-merge/auto-suggest (avoids PHI-mixing); smarter auto/suggested/reversible merge → FI6 | D38: Manual (chosen) | E38: 7.5 | F38: Yes — approved | G38: Cross-channel merge carries PHI-mixing risk (wrong merge blends two patients) and cross-channel signals are weak (IG/Messenger IDs ≠ phone). Hybrid auto-suggest rated 7.5; de-risked by choosing manual-only merge. | H38: phase-2b
A39: 2C | B39: Templates | C39: Clinic templates (reminders/confirmations/follow-ups) with variables; draft→submitted→approved/rejected (Meta-synced), versioned; managed in IA Studio; templates = only out-of-window path; Messenger/IG use message tags | D39: High | E39: 8.5 | H39: (pending record)
A40: 2C | B40: Six-gate | C40: Every proactive message passes 6 gates at the chokepoint: opt-out · approved-template · timing/eligibility · appointment-state-valid (cancellation cascade) · dedup/frequency-cap · clinic-enabled. Transactional-only scope | D40: High | E40: 8.5 | H40: (pending record)
A41: 2C | B41: Reminders | C41: On booking, schedule reminder/confirmation jobs (BullMQ delayed); fire through six-gate; confirm-reply → booked→confirmed; cancellation/reschedule cancels/reschedules queued jobs (1C cascade gets its subscriber) | D41: High | E41: 8.5 | H41: (pending record)
A42: 2C | B42: Follow-ups | C42: Automation engine subscribes to 1C auto-completion hook (+ no-show/cancel): completion → post-visit/review follow-up; no-show → recovery; template-gated via six-gate; per-clinic configurable (completes 1C seam) | D42: High | E42: 8.5 | H42: (pending record)
A43: 2C | B43: Broadcast | C43: DEFERRED (locked) — broadcast/marketing deferred to FI8 (build later w/ explicit opt-in + marketing templates + frequency caps + number-reputation safeguards); 2C ships transactional-only | D43: High | E43: 8.5 | H43: phase-2c
A44: 2D | B44: Analytics | C44: Metrics + QoS via scheduled rollup jobs into per-clinic aggregate tables (RLS): PR17 (totals, by-channel, leads, requests, scheduled, transfers, common Qs, peak hours, no-response, conversion) + PR32 (upset, abandoned, response times, no-closure, follow-up ops); dashboards in IA Studio + clinic panel | D44: High | E44: 8.5 | H44: (pending record)
A45: 2D | B45: Error review | C45: Review queue fed by error_log + DLQ + events: unanswered, bot-asked-help, bad responses, handoffs, unknown intents, Meta/Calendar errors, failed messages; categorized + actionable (unanswered → KB-suggestion loop) | D45: High | E45: 8.5 | H45: (pending record)
A46: 2D | B46: Content search | C46: Postgres full-text search (tsvector + GIN) over message content, strictly per-clinic (RLS) + audited; resolves R12 (deferred from 1B); semantic/pgvector search → FI | D46: High | E46: 8.5 | H46: (pending record)
A47: 3A | B47: Doctor entity | C47: Activate dormant doctor seam (P0): clinic has 1..N doctors; per-doctor calendar/services/hours/FAQs. Doctor = bookable profile, optionally linked to a user account w/ doctor role. Single-doctor = N=1 default (backward compatible) | D47: High | E47: 8.5 | H47: (pending record)
A48: 3A | B48: Doctor selection | C48: Extends locked 8-step intake: >1 doctor adds a selection step (explicit / specialty-inferred / 'any available' = earliest across doctors) then checks that doctor's calendar; single-doctor auto-skips | D48: High | E48: 8.5 | H48: (pending record)
A49: 3A | B49: Per-doctor KB | C49: Retrieval is doctor-aware once a doctor context is set: clinic-shared chunks + selected-doctor chunks; rules always-injected; no cross-doctor leakage; pre-selection answers at clinic level / lists doctors | D49: High | E49: 8.5 | H49: (pending record)
A50: 3A | B50: Doctor routing | C50: Conversations/appointments associate with a doctor; inbox filter by doctor; notifications route per-doctor-staffing or shared queue; doctor role sees own appts/convos (reuses 2A RBAC/routing) | D50: High | E50: 8 | H50: (pending record)
... A65: 0 | B65: Compliance | C65: Design to GDPR-style baseline (explicit consent, sensitive/health-data handling, retention limits, erasure, breach response) — safe superset of current Guatemalan law (no comprehensive PDP law yet; Decree 57-2008 criminalizes commercializing personal data w/o consent; Health Code protects health data; Initiative 6,105 pending). Never commercialize patient data; written consent for any export (ties SEC24); local-counsel review before launch (X20) | D65: High | E65: 8.5 | H65: cross-cutting

Sheet Update Log
A1: Date | B1: Ref | C1: Note
A2: 2026-06-13 | B2: Dev Plan | C2: Added two-agent development plan (Dev Plan tab + docmee-dev-plan.md + AGENTS.md + docmee-api-contract.yaml). Cut: Agent BE owns Core+Contract, Agent FE owns Experience; seam = packages/contracts (mock-first). Per-phase parallel tracks + integration checkpoints; CI-enforced import boundary; in-phase RLS + six-gate tests
A3: 2026-06-13 | B3: Build Backlog | C3: Added Build Backlog tab + docmee-build-backlog.md — sequenced from sealed plan: Sprint 0 (unblock Meta/counsel + SEC06) → Phase 0 → 1A–1C → Pilot launch gate → 2A–3D. Each stage carries its gates/gaps/actions/security. Two test layers (RLS, six-gate) flagged to build in-phase, not post-deploy
A4: 2026-06-13 | B4: Main confidence | C4: Added live Confidence section to Main dashboard (Phase 0→3D): total scored, average, lowest, and counts by tier (≥9 / 8.5 / 8.0 / <8) via COUNTIF on the Decisions Index score column; flags the one sub-8 (2B identity merge 7.5) + the 8.0 watch list
A5: 2026-06-13 | B5: Cross-cutting locked | C5: Closed the 4 potential-misses: LOCKED retention/erasure (D62, configurable + GDPR baseline), platform observability (D63, lean single-VPS), GDPR-baseline compliance (D64, per Guatemala law check — Decree 57-2008 + Health Code + Initiative 6,105). Gaps G62–G63. Security SEC25. Testing/QA → action X19 (non-blocking, post-deploy). Legal counsel → action X20
A6: 2026-06-13 | B6: ALL 12 PHASES SEALED | C6: Broadcast locked = DEFERRED to FI8 (2C transactional-only). 2C sweep G57–G61 locked (timezone, confirm-reply, template-rejection, frequency-cap, failed-send idempotency). Formally sealed 2C,2D,3A,3B,3C,3D → all 12 phases sealed. Planning phase complete; next step is build. Decisions finalized — gates/actions remain for implementation
A7: 2026-06-13 | B7: Gap-closure locked | C7: Locked recommendations for the 3 requirement gaps — PR21 ES+EN panel i18n (8.5), PR22 ES+EN chatbot (8.5), PR09 bot appt-status query (8.5; reschedule/cancel stay human, bot-driven → FI7). PR21 GAP→Planned, PR22 Partial→Planned. Requirements Partial/Gap now 1 (PR09 by design). Added FI7
A8: 2026-06-13 | B8: 3D Q1–Q3 | C8: Mobile/PWA/Push locked — PWA delivery (8.5), Web Push/VAPID into notification ladder (8.5), mobile parity for secretary ops (8.5). Sweep G52–G56 locked. PR23 PWA path locked (native=FI4), PR24 push locked. No flags
A9: 2026-06-13 | B9: Roadmap complete | C9: All 12 phases now have decisions locked (0,1A,1B,1C,2A,2B,2C,2D,3A,3B,3C,3D). Remaining open: 2C Q5 broadcast (parked) + 3 requirement gaps (PR21 panel i18n, PR22 English chatbot, PR09 bot reschedule/cancel+status). Formal phase seals pending
A10: 2026-06-13 | B10: Gap inventory (all) | C10: Full gap log — Gaps tab holds G01–G51, all Locked/Resolved. By phase: P0/1A/1B/1C foundation+sweeps G01–G25 · 2A G26–G28 · 2B G29–G31 · 2D G32–G36 · 3A G37–G41 · 3B G42–G46 · 3C G47–G51. Requirement gaps tracked separately on Platform Requirements (remaining: PR21 panel i18n GAP, PR22 English chatbot, PR09 bot reschedule/cancel — all surfaced on Main)
A11: 2026-06-13 | B11: 3C Q1–Q3 | C11: Integrations & OCR locked — OCR/rich-format ingestion (8.5), Sheets/CRM export (8.0), automated reports (8.5). Sweep G47–G51 locked. Added X18 (Sheets/CRM connect) + SEC24 (external data egress). PR25 Covered (OCR), PR31 export locked. No flags
A12: 2026-06-13 | B12: 3B Q1–Q3 | C12: Advanced Intake locked — declarative custom-flow builder (8.0), structured advanced rules w/ deterministic safety enforcement (8.5), human-in-the-loop secretary copilot (8.0). Sweep G42–G46 locked. Closed requirement gaps PR26/PR27/PR28 (Partial→Planned). No flags
... A57: 2026-06-13 | B57: Init | C57: Trackers created

Sheet Future Improvements
A1: ID | B1: Improvement | C1: Context / source | D1: Trigger — when to build | E1: Notes
A2: FI1 | B2: Real-time two-way Google Calendar sync (live push/webhook → update Docmee on external edits/deletes) | C2: Flagged at 1C Q1 (1C ships free/busy-at-booking + reconciliation only) | D2: Clinics heavily managing appointments directly in Google Calendar; post-1C release | E2: Calendar stays datetime source of truth; removes reconciliation lag
A3: FI2 | B3: Self-hosted LLM (e.g., RunPod) for cost optimization | C3: Architecture future mode (rollout-3) | D3: When LLM spend justifies / data-residency push | E3: Gateway already provider-abstracted — swap, not rebuild
A4: FI3 | B4: Commercial license control + self-hosted deployment (Ed25519 license server, Tauri installer, control plane) | C4: Architecture future modes | D4: When selling self-hosted / white-label installs | E4: Soft-enforcement contract still applies; placeholders only today
A5: FI4 | B5: Native mobile app | C5: Architecture future (only if PWA insufficient) | D5: If PWA proves inadequate for clinics | E5: PWA + push is the planned 3D path first
A6: FI5 | B6: Automated billing / payment gateway (e.g. Stripe) + dunning | C6: From 2A Q5 — 2A ships manual invoicing only | D6: When clinic count makes manual invoicing impractical | E6: Plan model already defined; this automates charge + collection
A7: FI6 | B7: Smarter cross-channel identity merge (verified auto-link on strong signals + duplicate suggestions + reversible merge) | C7: From 2B Q2 — 2B ships manual merge only | D7: When cross-channel duplicates become common / a reliable signal source exists | E7: Reduces manual merge effort; must preserve PHI-mixing safety
A8: FI7 | B8: Bot-driven reschedule / cancel via Calendar (guardrailed: confirmation + ownership checks + cancellation cascade) | C8: From PR09 gap-closure — bot does status-query now; reschedule/cancel stay human for safety | D8: Once bot reliability is proven and guardrails validated | E8: Spec wants bot reschedule/cancel; deferred deliberately — 1C routes these to humans
A9: FI8 | B9: Broadcast / marketing campaigns (promotional messages to patient lists) with explicit marketing opt-in + marketing templates + frequency caps + number-reputation safeguards | C9: From 2C Q5 — 2C ships transactional-only | D9: When promotional outreach is needed and opt-in consent infra is in place | E9: Higher compliance/spam/number-ban risk — must be consent-gated + rate-limited

Sheet Gaps
A1: ID | B1: Phase | C1: Gap (surfaced in sweep) | D1: Resolution / decision | E1: Status
A2: G01 | B2: 0 | C2: Migration tooling unspecified (how migrations run) | D2: Raw numbered SQL + minimal forward-only runner + schema_migrations; transactional apply | E2: Locked
A3: G02 | B3: 0 | C3: RLS context chokepoint — how clinic context is ALWAYS set | D3: withClinicContext() helper; raw pool private to packages/db; API preHandler + worker wrapper; single audited admin path | E3: Locked
A4: G03 | B4: 0 | C4: First clinic/admin bootstrap (chicken-and-egg; no public signup) | D4: Operator-run bootstrap seeds first platform admin (random pw, force-rotate); clinics via real create-clinic/invite-admin | E4: Locked
A5: G04 | B5: 0 | C5: Health-check depth (what 'green' verifies) | D5: /health liveness + /health/ready (Postgres+Redis+Vault; external providers excluded; ~5s cache); gate uses readiness | E5: Locked
A6: G05 | B6: 0 | C6: Secrets bootstrapping order (Vault circularity) | D6: Env = connection secrets only; master key fetched from Vault at boot; host-secret-store fallback; fail-fast to not-ready | E6: Locked
A7: G06 | B7: 0 | C7: Webhook verification handshake (subscribe before messages) | D7: Meta GET verify-challenge (constant-time) + HMAC POST + Evolution adapter registration | E7: Locked
A8: G07 | B8: 0 | C8: Deployment target undefined | D8: Single-VPS all-in-one for pilot; Supabase managed; redundancy → FI/X13 | E8: Locked
A9: G08 | B9: 0 | C9: Elevated-impersonation attribution seam | D9: Reserve nullable acted_by_platform_user_id now (empty in 0); behavior built 2A | E9: Locked
A10: G09 | B10: 1A | C10: Conversation lifecycle (new vs continue) | D10: >30 days → new conversation; resolved + inbound <7 days → reopen in bot mode; history uses current conversation | E10: Locked
A11: G10 | B11: 1A | C11: Bot disclosure to patient | D11: One-time lightweight disclosure in first bot reply of a new conversation; per-clinic, on by default | E11: Locked
A12: G11 | B12: 1A | C12: Outbound length / WhatsApp formatting | D12: Brevity in answer contract + split >4096 chars on paragraph boundaries (≤2–3 msgs); WhatsApp-supported formatting | E12: Locked
... A64: G63 | B64: 0 | C64: Consent capture for processing & export | D64: Explicit consent recorded; any export requires consent (Decree 57-2008 criminalizes commercializing data w/o consent; ties SEC24); sensitive/health-data handled with care | E64: Locked

Sheet Pros
A1: ID | B1: Phase | C1: Category | D1: Decision | E1: Description | F1: Pros
A2: D01 | B2: 0 | C2: Security | D2: Worker RLS | E2: Background jobs run under per-clinic DB context; one audited admin path | F2: Tenant isolation enforced at the DB for background jobs (not just API); single audited admin path
A3: D02 | B3: 0 | C3: Security | D3: Encryption | E3: PHI encrypted at rest via app-layer envelope + rotating key | F3: PHI encrypted at rest; app-layer envelope; key rotation via key_version
A4: D03 | B4: 0 | C4: Security | D4: Identities | E4: Platform admins and clinic users are separate identity systems | F4: Platform vs clinic users disjoint; clean privilege separation; impersonation audited
A5: D04 | B5: 0 | C5: Architecture | D5: Tenancy | E5: Each user belongs to exactly one clinic (one-to-one) | F5: Simple one-to-one user↔clinic; RLS isolation absolute
A6: D05 | B6: 0 | C6: Compliance | D6: Opt-out | E6: Opted-out patients suppressed at a single outbound chokepoint | F6: Compliance-grade outbound suppression at a single chokepoint; bot-irreversible
A7: D06 | B7: 0 | C7: Architecture | D7: Loop | E7: Phase 0 builds pipes only — no automatic patient replies yet | F7: Phase 0 ships pipes only; no premature auto-replies; safe foundation
A8: D07 | B8: 0 | C8: Architecture | D8: Idempotency | E8: Redelivered webhooks de-duplicated via unique provider message id | F8: Redelivered webhooks never double-process; exactly-once rows
A9: D08 | B9: 0 | C9: Deployment/Ops | D9: Deploy | E9: Single all-in-one VPS for the pilot; managed Supabase | F9: Single-VPS all-in-one — cheap, simple for the pilot
A10: D09 | B10: 0 | C10: Development | D10: Mechanisms | E10: Migrations, context wrapper, bootstrap, health, secrets, webhook handshake specified | F10: Migrations, context wrapper, bootstrap, health, secrets-boot, webhook handshake all specified — no ad-hoc gaps
A11: D10 | B11: 1A | C11: Development | D11: KB | E11: Unified KB (manual + docs); rules always injected; 0.70 retrieval | F11: Unified substrate (manual + docs); rules always-injected; grounded retrieval
A12: D11 | B12: 1A | C12: Architecture | D12: Pipeline | E12: Ordered gate chain; reply needs a pipeline-issued decision token | F12: Structurally-enforced gate ordering; reply can't emit without a decision token; safe by construction
... A65: D64 | B65: 0 | C65: Compliance | D65: Compliance | E65: GDPR-baseline compliance (Guatemala law + Initiative 6,105) | F65: GDPR baseline satisfies current Guatemalan criminal/consent rules + future-proofs for Initiative 6,105; reinforces export-consent

Sheet Cons
A1: ID | B1: Phase | C1: Category | D1: Decision | E1: Description | F1: Cons / tradeoffs
A2: D01 | B2: 0 | C2: Security | D2: Worker RLS | E2: Background jobs run under per-clinic DB context; one audited admin path | F2: Every worker must set clinic context — mitigated by withClinicContext() wrapper + lint
A3: D02 | B3: 0 | C3: Security | D3: Encryption | E3: PHI encrypted at rest via app-layer envelope + rotating key | F3: Encrypted fields not SQL-searchable → HMAC lookup keys needed (R4)
A4: D03 | B4: 0 | C4: Security | D4: Identities | E4: Platform admins and clinic users are separate identity systems | F4: Two identity systems to maintain
A5: D04 | B5: 0 | C5: Architecture | D5: Tenancy | E5: Each user belongs to exactly one clinic (one-to-one) | F5: Won't fit clinic-group customers without a migration (R6)
A6: D05 | B6: 0 | C6: Compliance | D6: Opt-out | E6: Opted-out patients suppressed at a single outbound chokepoint | F6: Opt-out must be checked on every outbound (enforced structurally)
A7: D06 | B7: 0 | C7: Architecture | D7: Loop | E7: Phase 0 builds pipes only — no automatic patient replies yet | F7: No user-visible behavior in Phase 0 (acceptable — foundation)
A8: D07 | B8: 0 | C8: Architecture | D8: Idempotency | E8: Redelivered webhooks de-duplicated via unique provider message id | F8: Requires provider_message_id uniqueness handling
A9: D08 | B9: 0 | C9: Deployment/Ops | D9: Deploy | E9: Single all-in-one VPS for the pilot; managed Supabase | F9: Single point of failure (R8); redundancy deferred (X13)
A10: D09 | B10: 0 | C10: Development | D10: Mechanisms | E10: Migrations, context wrapper, bootstrap, health, secrets, webhook handshake specified | F10: More upfront plumbing before features
A11: D10 | B11: 1A | C11: Development | D11: KB | E11: Unified KB (manual + docs); rules always injected; 0.70 retrieval | F11: Document ingestion expands 1A scope (R9 — top schedule risk)
A12: D11 | B12: 1A | C12: Architecture | D12: Pipeline | E12: Ordered gate chain; reply needs a pipeline-issued decision token | F12: Single-entry discipline adds indirection
... A65: D64 | B65: 0 | C65: Compliance | D65: Compliance | E65: GDPR-baseline compliance (Guatemala law + Initiative 6,105) | F65: Local-counsel confirmation still required; consent UX work; ongoing law-change monitoring

Sheet Progress
A1: Docmee — Progress Dashboard
A2: Indicative 26-week (6-month) plan · phase %s reflect sealed/in-progress status · charts are live
A4: Phase | B4: Start (wk) | C4: Duration (wk) | D4: End (wk) | E4: Status | F4: % Complete | G4: Done (wk) | H4: Remaining (wk)
A5: 0 — Foundation | B5: 0 | C5: 2 | D5: =B5+C5 -> 2 | E5: Sealed | F5: 100 | G5: =C5*F5/100 -> 2 | H5: =C5-G5 -> 0
A6: 1A — Core Bot | B6: 2 | C6: 4 | D6: =B6+C6 -> 6 | E6: Sealed | F6: 100 | G6: =C6*F6/100 -> 4 | H6: =C6-G6 -> 0
A7: 1B — Human Inbox | B7: 6 | C7: 3 | D7: =B7+C7 -> 9 | E7: Sealed | F7: 100 | G7: =C7*F7/100 -> 3 | H7: =C7-G7 -> 0
A8: 1C — Scheduling | B8: 9 | C8: 3 | D8: =B8+C8 -> 12 | E8: Sealed | F8: 100 | G8: =C8*F8/100 -> 3 | H8: =C8-G8 -> 0
A9: 2A — Multi-User Ops | B9: 12 | C9: 2 | D9: =B9+C9 -> 14 | E9: Sealed | F9: 100 | G9: =C9*F9/100 -> 2 | H9: =C9-G9 -> 0
A10: 2B — Channels | B10: 14 | C10: 2 | D10: =B10+C10 -> 16 | E10: Sealed | F10: 100 | G10: =C10*F10/100 -> 2 | H10: =C10-G10 -> 0
A11: 2C — Automation | B11: 16 | C11: 2 | D11: =B11+C11 -> 18 | E11: Sealed | F11: 100 | G11: =C11*F11/100 -> 2 | H11: =C11-G11 -> 0
A12: 2D — Analytics/Search | B12: 18 | C12: 2 | D12: =B12+C12 -> 20 | E12: Sealed | F12: 100 | G12: =C12*F12/100 -> 2 | H12: =C12-G12 -> 0
A13: 3A — Multi-Doctor | B13: 20 | C13: 2 | D13: =B13+C13 -> 22 | E13: Sealed | F13: 100 | G13: =C13*F13/100 -> 2 | H13: =C13-G13 -> 0
A14: 3B — Adv. Intake | B14: 22 | C14: 1 | D14: =B14+C14 -> 23 | E14: Sealed | F14: 100 | G14: =C14*F14/100 -> 1 | H14: =C14-G14 -> 0
A15: 3C — Integrations/OCR | B15: 23 | C15: 2 | D15: =B15+C15 -> 25 | E15: Sealed | F15: 100 | G15: =C15*F15/100 -> 2 | H15: =C15-G15 -> 0
A16: 3D — Mobile/PWA/Push | B16: 25 | C16: 1 | D16: =B16+C16 -> 26 | E16: Sealed | F16: 100 | G16: =C16*F16/100 -> 1 | H16: =C16-G16 -> 0
A19: Deployment / external actions (from Action Tracker)
A20: Status | B20: Count
A21: Not started | B21: =COUNTIF('Action Tracker'!F2:F21,"Not started") -> 15
A22: In progress | B22: =COUNTIF('Action Tracker'!F2:F21,"In progress") -> 2
A23: Closed (done) | B23: =COUNTIF('Action Tracker'!F2:F21,"Closed*") -> 1
A24: Blocked/waiting | B24: =COUNTIF('Action Tracker'!F2:F21,"Blocked/waiting") -> 1
A25: Parked | B25: =COUNTIF('Action Tracker'!F2:F21,"Parked") -> 1
A28: Overall project — phases
A29: Status | B29: Count
A30: Sealed | B30: =COUNTIF(E5:E16,"Sealed") -> 12
A31: In progress | B31: =COUNTIF(E5:E16,"In progress") -> 0
A32: Pending | B32: =COUNTIF(E5:E16,"Pending") -> 0
A34: Overall % complete | B34: =AVERAGE(F5:F16) -> 100
A37: Requirements delivery schedule (source for Requirements Gantt)
A38: Requirement | B38: Start (wk) | C38: Delivered (wk) | D38: Remaining (wk) | E38: Phase
A39: PR01 IA Studio | B39: 12 | C39: 2 | D39: 0 | E39: 2A
A40: PR02 Clinic Panel | B40: 6 | C40: 3 | D40: 0 | E40: 1B
A41: PR03 Channels | B41: 2 | C41: 4 | D41: 0 | E41: 1A
A42: PR04 Unified Inbox | B42: 6 | C42: 3 | D42: 0 | E42: 1B
A43: PR05 Bot/Human Mode | B43: 2 | C43: 4 | D43: 0 | E43: 1A
A44: PR06 No-Interrupt | B44: 2 | C44: 4 | D44: 0 | E44: 1A
A45: PR07 KB | B45: 2 | C45: 4 | D45: 0 | E45: 1A
A46: PR08 Audio | B46: 2 | C46: 4 | D46: 0 | E46: 1A
A47: PR09 Calendar | B47: 9 | C47: 3 | D47: 0 | E47: 1C
A48: PR10 Data Capture | B48: 6 | C48: 3 | D48: 0 | E48: 1B
...

Sheet Security Audit
A1: ID | B1: Category | C1: Concern | D1: Details | E1: Blast radius | F1: Priority | G1: Recommended solution | H1: Status
A2: SEC01 | B2: Tenant Isolation | C2: Cross-tenant RLS carve-out leak | D2: A worker/admin code path missing clinic context could read or write across tenants | E2: Catastrophic — all clinics' PHI exposed/crossed | F2: Critical | G2: withClinicContext() everywhere; single named admin role via withAdminContext() (lint-enforced single import) + allowlist + audit (R5) | H2: Mitigated (locked)
A3: SEC02 | B3: Encryption / Keys | C3: Master encryption key compromise | D3: Envelope-encryption master key leak exposes all PHI at rest | E3: Catastrophic — all PHI at rest | F3: Critical | G3: Supabase Vault + envelope + key_version rotation + host-store fallback; restrict key access; rotate on suspicion (X8) | H3: Mitigated (locked)
A4: SEC03 | B4: Encryption / Keys | C4: HMAC lookup-key leak (identity correlation) | D4: Stable HMAC used for encrypted-field lookups; leak enables correlation/brute-force of identities | E4: High — patient identity correlation | F4: High | G4: Separate stable HMAC key, independent of the encryption key; long key; restricted access (R4) | H4: Mitigated (locked)
A5: SEC04 | B5: Third-Party | C5: PHI through unofficial WhatsApp gateway (Evolution) | D5: Interim transport is an unofficial gateway — PHI in transit through a non-official component; ToS + interception risk | E5: High — WhatsApp PHI in transit | F5: High | G5: Bounded interim + supervision; per-clinic cutover to official Meta Cloud API (R7, X9/X10) | H5: Mitigated (interim); cutover planned
A6: SEC05 | B6: Application / Bot | C6: Prompt injection / data exfiltration via patient input | D6: Patient messages may try to manipulate the bot to reveal data or act out of scope | E6: Medium-High — bounded to current clinic/patient by RLS | F6: High | G6: KB-grounded only (no general fallback); RLS-scoped context; DAL allowlist constrains writes; structured system prompt; deterministic gates | H6: Mitigated (by design)
A7: SEC06 | B7: Third-Party | C7: PHI sent to third-party LLM/ASR providers | D7: Messages/audio sent to Anthropic/DeepSeek/OpenAI/Deepgram; data-handling + residency concerns for medical data | E7: High — PHI to external processors | F7: High | G7: Provider data-processing terms + no-train assurances; minimize PHI in prompts; consider self-hosted LLM (FI2) for sensitive deployments | H7: Open — review needed
A8: SEC07 | B8: Auth / Access | C8: RBAC enforced only in UI (privilege escalation) | D8: If the role matrix isn't enforced at API/DAL, a user could call APIs beyond their role | E8: Medium — within-clinic over-access | F8: High | G8: Enforce the 5-role matrix at API/DAL, not UI-only (G18) | H8: Mitigated (locked)
A9: SEC08 | B9: Auth / Access | C9: Platform impersonation abuse | D9: Platform admins can impersonate clinic users; abuse = access to any clinic's PHI | E9: High — any clinic via impersonation | F9: High | G9: acted_by_platform_user_id stamp + audit + time-boxed session + platform-only (G28) | H9: Mitigated (locked)
A10: SEC09 | B10: Network / Transport | C10: Webhook spoofing (unverified inbound) | D10: Unverified Meta webhooks allow forged inbound messages | E10: Medium — injected messages per clinic | F10: High | G10: Meta HMAC signature verification + constant-time compare + verify-challenge (G06) | H10: Mitigated (locked)
A11: SEC10 | B11: Application / Bot | C11: Bot unauthorized data writes | D11: Bot writes to patient records; injection could attempt bad writes | E11: Medium — single patient record | F11: High | G11: DAL allowlist (field-level, validated, logged, NO deletes), confidence-gated, secretary-wins (D24) | H11: Mitigated (locked)
A12: SEC11 | B12: Encryption / Keys | C12: Secrets exposure (env / boot) | D12: Connection secrets in env; leak via misconfig or logs | E12: High — infra credentials | F12: High | G12: env = connection secrets only; master key from Vault at boot; fail-fast; never log secrets (G05) | H12: Mitigated (locked)
... A26: SEC25 | B26: Compliance | C26: Data retention & right-to-erasure | D26: No retention/erasure policy = indefinite PHI accumulation + no deletion path; non-compliant with GDPR-baseline + emerging Guatemalan law | E26: Medium — long-term PHI exposure surface | F26: Medium | G26: Configurable retention + scheduled hard-purge cascade (D62/G62); right-to-erasure via opt-out chokepoint; consent capture (G63); local-counsel review (X20) | H26: Mitigated (D62 retention + G62 cascade)

Sheet Platform Requirements
A1: Platform Requirements — spec vs. build cross-check
A2: Source: Docmee_Platform_Requirements_EN.pdf · doc Phase 1→our 0/1A/1B/1C · doc Phase 2→our 2A–2D · doc Phase 3→our 3A–3D
A4: ID | B4: Doc section | C4: Requirement (grouped) | D4: Coverage | E4: Where (our build) | F4: Notes
A5: PR01 | B5: 1. IA Studio Admin Panel | C5: Create/activate clinics, users, roles, chatbot settings, view convos, manage channels, error review, performance, billing, integrations | D5: Planned | E5: 2A (IA Studio+RBAC D33), 2A invoicing (D34), 2D error review | F5: Core admin surface in 2A; billing manual in 2A
A6: PR02 | B6: 2. Clinic Panel | C6: Private per-clinic panel; multi-user roles (doctor/secretary/admin/assistant); role permissions | D6: Covered | E6: 1B (panel/CRM), 2A (RBAC D33) | F6: 5-role matrix locked + enforced at API/DAL
A7: PR03 | B7: 3. Communication Channels | C7: WhatsApp first; then Messenger + Instagram; unified inbox | D7: Covered | E7: 1A (WhatsApp), 2B (Messenger/IG + unified)
A8: PR04 | B8: 4. Unified Inbox | C8: Conversation states, name/phone, channel, history, status, tags, notes, appt status, last interaction | D8: Covered | E8: 1A/1B/2B
A9: PR05 | B9: 5. Bot/Human Mode | C9: Activate/pause/transfer/return bot; detect human-request phrases; mark urgent | D9: Covered | E9: 1A (modes, takeover, intent/handoff, deflection)
A10: PR06 | B10: 6. Bot Must Not Interrupt | C10: Human reply pauses bot; assigned = bot silent; manual/timeout reactivation; show mode | D10: Covered | E10: 1A (takeover-on-reply + self-healing handback) | F10: Core locked principle
A11: PR07 | B11: 7. KB Per Clinic | C11: Own KB; answer only clinic info; rich fields; IA Studio edit; no cross-clinic mixing | D11: Covered | E11: 1A (KB + RLS isolation + grounding)
A12: PR08 | B12: 8. Audio Messages | C12: Transcribe → understand → text reply; audio replies future | D12: Covered | E12: 1A (provider-abstracted transcription)
A13: PR09 | B13: 9. Google Calendar | C13: Availability, schedule, confirm, reschedule, cancel, check existing appt, status query, transfer if not found | D13: Partial | E13: 1C (schedule/availability), 2C (confirm), gap-closure (bot status-query) | F13: Closed by decision: bot now answers appt-status query (reads Calendar, not-found→human); reschedule/cancel DELIBERATELY human-routed for safety (bot-driven → FI7)
A14: PR10 | B14: 10. Patient Data Capture | C14: Name, phone, reason, preferred date/time, doctor/specialty, new/returning, channel, notes | D14: Covered | E14: 1B (capture D24) + 1C (intake); doctor/specialty → 3A
A15: PR11 | B15: 11. Tags & Statuses | C15: Suggested tags + conversation statuses | D15: Covered | E15: 1B (tags + patient status; conversation status = mode) | F15: Mode (bot/human/paused/resolved) maps to the doc's statuses; no duplicate status system
A16: PR12 | B16: 12. Conversation Assignment | C16: Assign to secretaries / doctor / admin | D16: Covered | E16: 1B (assignment) + 2A (routing D30)
A17: PR13 | B17: 13. Internal Notes | C17: Staff-only notes inside conversations | D17: Covered | E17: 1B (patient/conversation notes D22)
A18: PR14 | B18: 14. Follow-Ups & Reminders | C18: 1-day reminder, confirmation, post-consult, 7-day, 3-month, review, no-reply; template-gated | D18: Covered | E18: 2C (reminders/confirmations/follow-ups, six-gate, templates)
A19: PR15 | B19: 15. Quick Reply Templates | C19: Canned responses (address/hours/price/etc.) | D19: Covered | E19: 2A (quick replies D32)
A20: PR16 | B20: 16. Patient History | C20: Prev convos/appointments, status, notes, tags, last interaction, next appt; not a medical record | D20: Covered | E20: 1B (profile) + 1C (appointments)
A21: PR17 | B21: 17. Basic Metrics | C21: Totals, by channel, leads, requests, scheduled, transfers, common Qs, peak hours, no-response, conversion | D21: Planned | E21: 2D (Analytics)
A22: PR18 | B22: 18. Secretary Alerts | C22: Human-request, bot-stuck, appt request, urgent, upset, needs confirmation, repeated no-response | D22: Covered | E22: 1B (notifications) + 2A (full escalation D31)
A23: PR19 | B23: 19. Meta Compliance & Account Protection | C23: API use, verification, webhooks, token storage/renewal, windows, approved templates, no mass-msg w/o consent, consent, opt-out, anti-spam, quality monitoring, Meta error logs | D23: Covered | E23: P0 (webhook/tokens/opt-out), 1A (window), 2C (templates/six-gate/consent), 2D (quality/error logs), X1/X3/X4 | F23: 'No mass messaging w/o consent' = 2C Q5 broadcast flag
A24: PR20 | B24: 20. Medical Safety Rules | C24: No diagnose/prescribe/treat/interpret/replace; suggest appointment; emergency → emergency services | D24: Covered | E24: 1A (deflection guardrail + behavioral rules D16)
A25: PR21 | B25: 21. Spanish & English PANEL | C25: Panel i18n; language switch; applies to all admin/clinic UI | D25: Planned | E25: Gap-closure (i18n framework from start) across panel | F25: LOCKED — ES+EN panel i18n: keys + per-user locale switch across IA Studio + clinic panel; panel language independent of chatbot
A26: PR22 | B26: 22. Spanish & English CHATBOT | C26: Bot understands + replies in patient language (Spanish + English) | D26: Planned | E26: Gap-closure (amends 1A): detect + respond in patient language | F26: LOCKED — ES+EN chatbot: detect patient language, reply in it using clinic-approved info; further languages → FI
A27: PR23 | B27: 23. Mobile App Vision | C27: Eventual app (UChat-like); responsive → PWA → native | D27: Planned | E27: 3D (PWA + Web Push) + FI4 (native app) | F27: Locked in 3D — responsive panel + installable PWA + push; native iOS/Android remains FI4
A28: PR24 | B28: 24. Notifications | C28: Triggers; web panel / email / mobile-PWA / internal-WhatsApp (future) | D28: Covered | E28: 1B + 2A (panel/email) + 3D (Web Push); internal-WhatsApp = future | F28: Push channel locked in 3D (VAPID) into the notification ladder
A29: PR25 | B29: 25. Document Training | C29: PDF/Word/text/FAQ ingestion into the KB | D29: Covered | E29: 1A (text-layer) + 3C (OCR + docx/structured parsers) | F29: Basic text ingestion in 1A; OCR for scanned docs + rich formats locked in 3C
A30: PR26 | B30: 26. Bot Tone Control | C30: Formal / friendly / professional / short / detailed / secretary-style | D30: Planned | E30: 3B (tone = per-clinic rule setting) + 1A | F30: Locked in 3B advanced rules — tone becomes a structured per-clinic rule
A31: PR27 | B31: 27. Clinic-Specific Rules | C31: No prices / only consult price / no medical Q / transfer emergencies / no booking w/o payment / after-hours data-only / transfer certain cases | D31: Planned | E31: 3B (structured conditional rules) + 1A (D10/D16) | F31: Locked in 3B — safety-critical rules (payment-gate, after-hours) enforced deterministically at pipeline gates
A32: PR28 | B32: 28. Custom Flows | C32: Schedule/reschedule/confirm/location/price/surgery/post-consult/review/insurance | D32: Planned | E32: 3B (declarative flow builder) + 1C/2C/1A | F32: Locked in 3B — clinic-configurable flow builder + starter library; individual flows already exist
A33: PR29 | B33: 29. Error Review Area | C33: Unanswered, help requests, bad responses, handoffs, unknown intents, Meta/Calendar errors, failed messages | D33: Planned | E33: 2D (error review) | F33: Infra exists: error_log/DLQ
A34: PR30 | B34: 30. Multi-Doctor Clinics | C34: Multiple doctors; per-doctor calendar/services/hours/FAQs; scheduling by doctor | D34: Planned | E34: 3A (Multi-Doctor) | F34: Seam reserved since Phase 0 (dormant doctor tables)
A35: PR31 | B35: 31. Sheets / CRM Integration | C35: Export patient/lead fields to Sheets or external CRM | D35: Planned | E35: 3C (Sheets append + generic webhook/CRM connector) | F35: Locked in 3C — per-clinic export, encrypted creds (X18), clinic-authorized fields only (SEC24)
A36: PR32 | B36: 32. QoS Monitoring | C36: Upset patients, abandoned, response times, no closure, no-schedule reasons, follow-up opportunities | D36: Planned | E36: 2D (QoS/analytics)

Sheet Cost Tracker
A1: Docmee — Cost Tracker
A2: Deliverables vs. time spent and AI-assistant cost. Blue input cells are editable; costs are live formulas. Fill Actual hrs + AI uses as you go.
A4: Assumptions (edit these)
A5: Parameter | B5: Value
A6: Dev rate ($/hr) | B6: 20
A7: AI cost per use ($/session) | B7: 0.5
A8: Hours per week (capacity) | B8: 25
A10: Cost tracker (by deliverable)
A11: ID | B11: Deliverable | C11: Weeks | D11: Est. hrs | E11: Actual hrs | F11: Dev cost | G11: AI uses | H11: AI cost | I11: Total cost | J11: Notes
A12: P0 | B12: 0 — Foundation | C12: 2 | D12: =C12*$B$8 -> 50 | F12: =N(E12)*$B$6 -> 0 | H12: =N(G12)*$B$7 -> 0 | I12: =F12+H12 -> 0
A13: P1A | B13: 1A — Core Bot | C13: 4 | D13: =C13*$B$8 -> 100 | F13: =N(E13)*$B$6 -> 0 | H13: =N(G13)*$B$7 -> 0 | I13: =F13+H13 -> 0
A14: P1B | B14: 1B — Human Inbox | C14: 3 | D14: =C14*$B$8 -> 75 | F14: =N(E14)*$B$6 -> 0 | H14: =N(G14)*$B$7 -> 0 | I14: =F14+H14 -> 0
A15: P1C | B15: 1C — Scheduling | C15: 3 | D15: =C15*$B$8 -> 75 | F15: =N(E15)*$B$6 -> 0 | H15: =N(G15)*$B$7 -> 0 | I15: =F15+H15 -> 0
A16: P2A | B16: 2A — Multi-User Ops | C16: 2 | D16: =C16*$B$8 -> 50 | F16: =N(E16)*$B$6 -> 0 | H16: =N(G16)*$B$7 -> 0 | I16: =F16+H16 -> 0
A17: P2B | B17: 2B — Channels | C17: 2 | D17: =C17*$B$8 -> 50 | F17: =N(E17)*$B$6 -> 0 | H17: =N(G17)*$B$7 -> 0 | I17: =F17+H17 -> 0
A18: P2C | B18: 2C — Automation | C18: 2 | D18: =C18*$B$8 -> 50 | E18: 1.5 | F18: =N(E18)*$B$6 -> 30 | G18: 6 | H18: =N(G18)*$B$7 -> 3 | I18: =F18+H18 -> 33 | J18: 2C Q1–Q4 decision work (this session) — estimate
A19: P2D | B19: 2D — Analytics/Search | C19: 2 | D19: =C19*$B$8 -> 50 | F19: =N(E19)*$B$6 -> 0 | H19: =N(G19)*$B$7 -> 0 | I19: =F19+H19 -> 0
A20: P3A | B20: 3A — Multi-Doctor | C20: 2 | D20: =C20*$B$8 -> 50 | F20: =N(E20)*$B$6 -> 0 | H20: =N(G20)*$B$7 -> 0 | I20: =F20+H20 -> 0
A21: P3B | B21: 3B — Adv. Intake | C21: 1 | D21: =C21*$B$8 -> 25 | F21: =N(E21)*$B$6 -> 0 | H21: =N(G21)*$B$7 -> 0 | I21: =F21+H21 -> 0
A22: P3C | B22: 3C — Integrations/OCR | C22: 2 | D22: =C22*$B$8 -> 50 | F22: =N(E22)*$B$6 -> 0 | H22: =N(G22)*$B$7 -> 0 | I22: =F22+H22 -> 0
A23: P3D | B23: 3D — Mobile/PWA/Push | C23: 1 | D23: =C23*$B$8 -> 25 | F23: =N(E23)*$B$6 -> 0 | H23: =N(G23)*$B$7 -> 0 | I23: =F23+H23 -> 0
A24: PM | B24: PM — Planning, decisions & tracker (cross-cutting) | C24: 0 | D24: =C24*$B$8 -> 0 | E24: 3.5 | F24: =N(E24)*$B$6 -> 70 | G24: 18 | H24: =N(G24)*$B$7 -> 9 | I24: =F24+H24 -> 79 | J24: This session: tracker build, dark mode, Gantts, Platform Requirements, Cost Tracker, Overview fixes — estimate
B25: TOTAL | C25: =SUM(C12:C24) -> 26 | D25: =SUM(D12:D24) -> 650 | E25: =SUM(E12:E24) -> 5 | F25: =SUM(F12:F24) -> 100 | G25: =SUM(G12:G24) -> 24 | H25: =SUM(H12:H24) -> 12 | I25: =SUM(I12:I24) -> 112
A27: Summary
A28: Total dev cost | B28: =F25 -> 100
A29: Total AI cost | B29: =H25 -> 12
A30: Grand total | B30: =I25 -> 112
A31: Est. hrs (plan) | B31: =D25 -> 650
A32: Actual hrs (logged) | B32: =E25 -> 5
A33: AI uses (logged) | B33: =G25 -> 24

Sheet Build Backlog
A1: Docmee — Build Backlog (sequenced from sealed plan)
A2: Build top-to-bottom. Gates = definition of done · Gaps = impl rules · Actions/Security = pre-conditions. Companion: docmee-build-backlog.md
A4: Order | B4: Stage | C4: Build focus | D4: Gates | E4: Gaps | F4: Actions (pre-cond) | G4: Security | H4: Notes
A5: S0 | B5: Sprint 0 | C5: Setup + unblock externals + SEC06 decision | D5: — | E5: — | F5: X7·X20·X1·X5·X6·X2·X9 | G5: SEC06·SEC22 | H5: Start Meta + counsel NOW (lead time); stand up infra + CI + observability (D63)
A6: 1 | B6: Phase 0 — Foundation | C6: RLS isolation · encryption · opt-out chokepoint · idempotency · deploy | D6: 9 | E6: G01–G08·G62·G63 | F6: X6 | G6: SEC16 | H6: Build the RLS tenant-isolation test suite here
A7: 2 | B7: Phase 1A — Core Bot | C7: KB · 5-intent pipeline · 24h window · transcription · ES/EN bot | D7: 10 | E7: G09–G13 | F7: X5 | G7: SEC06 | H7: Grounded answers; never interrupts a human
A8: 3 | B8: Phase 1B — Human Inbox | C8: Patient CRM · assignment · tags · notes · capture allowlist | D8: 16 | E8: G14–G18 | F8: — | G8: — | H8: Secretaries fully operate inbox
A9: 4 | B9: Phase 1C — Scheduling | C9: Calendar truth · 8-step intake · lifecycle · status query | D9: 14 | E9: G19–G25 | F9: X15 | G9: — | H9: Reschedule/cancel route to humans
A10: ★ | B10: PILOT LAUNCH GATE | C10: Pre-conditions before ANY real patient traffic | D10: — | E10: — | F10: X3·X7·X12·X14·X11·X20 | G10: SEC14·SEC18 | H10: All must pass before go-live
A11: 5 | B11: Phase 2A — Multi-User Ops | C11: RBAC · IA Studio · routing · notifications · panel i18n | D11: 11 | E11: G26–G28 | F11: — | G11: — | H11: ES/EN panel i18n here
A12: 6 | B12: Phase 2B — Channels | C12: Messenger + IG · unified inbox · manual merge | D12: 8 | E12: G29–G31 | F12: X16 | G12: — | H12: Manual merge only (FI6 later)
A13: 7 | B13: Phase 2C — Automation | C13: Templates · six-gate · reminders · follow-ups | D13: 4 | E13: G57–G61 | F13: X4 | G13: SEC23 | H13: Build six-gate + idempotency test suite here
A14: 8 | B14: Phase 2D — Analytics & Search | C14: Metrics/QoS rollups · error review · content search | D14: 3 | E14: G32–G36 | F14: — | G14: SEC16 | H14: Resolves R12
A15: 9 | B15: Phase 3A — Multi-Doctor | C15: Doctor entity · selection · per-doctor KB/routing | D15: 4 | E15: G37–G41 | F15: X17 | G15: — | H15: N=1 backward compatible
... A19: ~ | B19: Ongoing / parked | C19: Testing (X19) · observability (D63) · HA (X13 parked) | D19: — | E19: — | F19: X19·X11·X13 | G19: SEC06·14·16·18·22 | H19: Pull RLS+six-gate tests into the build

Sheet Dev Plan
A1: Docmee — Two-Agent Development Plan
A2: Shared monorepo · Agent BE (Core & Contract) + Agent FE (Experience). Seam = packages/contracts (BE owns, FE consumes via mock). Companion: docmee-dev-plan.md · AGENTS.md · docmee-api-contract.yaml
A4: Phase | B4: Agent BE track | C4: Agent FE track | D4: Integration checkpoint
A5: Sprint 0 | B5: Infra · CI · RLS test harness · SEC06 decision · contract v0 | C5: App shell · auth · design system · i18n framework · mock server | D5: Auth round-trips on real API
A6: 0 Foundation | B6: RLS · encryption · chokepoint · idempotency · deploy | C6: Login · clinic-switch · settings scaffold (mocked) | D6: Tenant-scoped session end-to-end
A7: 1A Core Bot (BE-heavy) | B7: KB · 5-intent pipeline · six-gate · transcription · ES/EN bot | C7: KB editor UI · inbox shell (mocked) · bot-mode toggle | D7: KB CRUD live; message hits inbox
A8: 1B Human Inbox (FE-heavy) | B8: Patient/conversation/notes APIs · assignment · capture allowlist | C8: Unified inbox · CRM · assignment · notes · tags | D8: Inbox operates on real data
A9: 1C Scheduling (balanced) | B9: Calendar truth · intake state machine · lifecycle | C9: Booking/calendar UI · appointment views | D9: Book → calendar + panel
A10: ★ PILOT LAUNCH GATE | B10: Rate-limiting (SEC18) · backups (X12) | C10: Polish · empty/error states · a11y | D10: Launch-gate checklist green
A11: 2A Multi-User | B11: RBAC · routing · notifications · invoicing | C11: Role mgmt · IA Studio · panel i18n · quick replies | D11: RBAC enforced UI + API
A12: 2B Channels | B12: Messenger/IG adapters · unified pipeline | C12: Channel badges · connect flow · merge UI | D12: Cross-channel msg in one inbox
A13: 2C Automation | B13: Templates · six-gate jobs · reminders | C13: Template manager · automation settings | D13: Reminder fires through six-gate
A14: 2D Analytics | B14: Rollups · error-review · FTS | C14: Dashboards · error-review UI · search | D14: Charts from real rollups
A15: 3A Multi-Doctor | B15: Doctor entity · per-doctor calendar/KB | C15: Doctor mgmt · doctor-select in booking | D15: Book a specific doctor
... A18: 3D Mobile/PWA | B18: Push service (VAPID) | C18: PWA manifest/SW · push opt-in · responsive | D18: Installable PWA gets a push
A20: The rule that makes two agents work
A21: • Backend owns packages/contracts (OpenAPI). Frontend consumes generated types + a mock until each phase's real endpoints land.
A22: • Hard import boundary (CI-enforced): FE never imports apps/api; BE never imports apps/web. CODEOWNERS per workspace.
A23: • Contract changes = isolated PR reviewed by both. Never bundle with feature code.
A24: • When blocked, author the next contract stub or write tests — do NOT cross into the other agent's lane.
A25: • Mandatory in-phase tests: RLS isolation (Phase 0), six-gate + idempotency (2C). Every PR maps to a tracker gate/gap.
